<?xml version="1.0" ?>
<!-- =================================================================================== -->
<!-- |    This document was autogenerated by xacro from /home/suja/voxel_ws/src/robot_base/urdf/four_diff.xacro | -->
<!-- |    EDITING THIS FILE BY HAND IS NOT RECOMMENDED                                 | -->
<!-- =================================================================================== -->
<robot name="robotcar">
  <!-- Base Footprint -->
  <link name="base_footprint"/>
  <joint name="base_joint" type="fixed">
    <parent link="base_footprint"/>
    <child link="base_link"/>
    <origin rpy="0 0 0" xyz="0 0 0.08"/>
  </joint>
  <!-- Base Link -->
  <link name="base_link">
    <visual>
      <geometry>
        <box size="0.68 0.33 0.3"/>
      </geometry>
      <material name="blue">
        <color rgba="0 0 1 1"/>
      </material>
      <origin rpy="0 0 0" xyz="0 0 0.15"/>
    </visual>
    <collision>
      <geometry>
        <box size="0.68 0.33 0.3"/>
      </geometry>
      <origin rpy="0 0 0" xyz="0 0 0.15"/>
    </collision>
    <inertial>
      <mass value="10.0"/>
      <origin xyz="0 0 0.15"/>
      <inertia ixx="0.1" ixy="0.0" ixz="0.0" iyy="0.1" iyz="0.0" izz="0.1"/>
    </inertial>
  </link>
  <!-- IMU Link (Center of body) -->
  <link name="imu_link"/>
  <joint name="imu_joint" type="fixed">
    <parent link="base_link"/>
    <child link="imu_link"/>
    <origin rpy="0 0 0" xyz="0 0 0.15"/>
  </joint>
  <!-- Livox Link (Front Top Edge) -->
  <link name="livox_frame"/>
  <joint name="livox_joint" type="fixed">
    <parent link="base_link"/>
    <child link="livox_frame"/>
    <origin rpy="0 -0.785398 0" xyz="0.34 0 0.3"/>
    <!-- 绕 Y 轴向上倾斜 45 度补偿物理向下角度，使scan水平 -->
  </joint>
  <link name="front_left_wheel_link">
    <visual>
      <geometry>
        <cylinder length="0.04" radius="0.08"/>
      </geometry>
      <material name="black">
        <color rgba="0 0 0 1"/>
      </material>
      <origin rpy="1.5707963267948966 0 0" xyz="0 0 0"/>
    </visual>
    <collision>
      <geometry>
        <cylinder length="0.04" radius="0.08"/>
      </geometry>
      <origin rpy="1.5707963267948966 0 0" xyz="0 0 0"/>
    </collision>
    <inertial>
      <mass value="1.0"/>
      <origin xyz="0 0 0"/>
      <inertia ixx="0.01" ixy="0.0" ixz="0.0" iyy="0.01" iyz="0.0" izz="0.01"/>
    </inertial>
  </link>
  <joint name="front_left_wheel_joint" type="continuous">
    <parent link="base_link"/>
    <child link="front_left_wheel_link"/>
    <origin rpy="0 0 0" xyz="0.2025 0.13 0"/>
    <axis xyz="0 1 0"/>
  </joint>
  <link name="front_right_wheel_link">
    <visual>
      <geometry>
        <cylinder length="0.04" radius="0.08"/>
      </geometry>
      <material name="black">
        <color rgba="0 0 0 1"/>
      </material>
      <origin rpy="1.5707963267948966 0 0" xyz="0 0 0"/>
    </visual>
    <collision>
      <geometry>
        <cylinder length="0.04" radius="0.08"/>
      </geometry>
      <origin rpy="1.5707963267948966 0 0" xyz="0 0 0"/>
    </collision>
    <inertial>
      <mass value="1.0"/>
      <origin xyz="0 0 0"/>
      <inertia ixx="0.01" ixy="0.0" ixz="0.0" iyy="0.01" iyz="0.0" izz="0.01"/>
    </inertial>
  </link>
  <joint name="front_right_wheel_joint" type="continuous">
    <parent link="base_link"/>
    <child link="front_right_wheel_link"/>
    <origin rpy="0 0 0" xyz="0.2025 -0.13 0"/>
    <axis xyz="0 1 0"/>
  </joint>
  <link name="rear_left_wheel_link">
    <visual>
      <geometry>
        <cylinder length="0.04" radius="0.08"/>
      </geometry>
      <material name="black">
        <color rgba="0 0 0 1"/>
      </material>
      <origin rpy="1.5707963267948966 0 0" xyz="0 0 0"/>
    </visual>
    <collision>
      <geometry>
        <cylinder length="0.04" radius="0.08"/>
      </geometry>
      <origin rpy="1.5707963267948966 0 0" xyz="0 0 0"/>
    </collision>
    <inertial>
      <mass value="1.0"/>
      <origin xyz="0 0 0"/>
      <inertia ixx="0.01" ixy="0.0" ixz="0.0" iyy="0.01" iyz="0.0" izz="0.01"/>
    </inertial>
  </link>
  <joint name="rear_left_wheel_joint" type="continuous">
    <parent link="base_link"/>
    <child link="rear_left_wheel_link"/>
    <origin rpy="0 0 0" xyz="-0.2025 0.13 0"/>
    <axis xyz="0 1 0"/>
  </joint>
  <link name="rear_right_wheel_link">
    <visual>
      <geometry>
        <cylinder length="0.04" radius="0.08"/>
      </geometry>
      <material name="black">
        <color rgba="0 0 0 1"/>
      </material>
      <origin rpy="1.5707963267948966 0 0" xyz="0 0 0"/>
    </visual>
    <collision>
      <geometry>
        <cylinder length="0.04" radius="0.08"/>
      </geometry>
      <origin rpy="1.5707963267948966 0 0" xyz="0 0 0"/>
    </collision>
    <inertial>
      <mass value="1.0"/>
      <origin xyz="0 0 0"/>
      <inertia ixx="0.01" ixy="0.0" ixz="0.0" iyy="0.01" iyz="0.0" izz="0.01"/>
    </inertial>
  </link>
  <joint name="rear_right_wheel_joint" type="continuous">
    <parent link="base_link"/>
    <child link="rear_right_wheel_link"/>
    <origin rpy="0 0 0" xyz="-0.2025 -0.13 0"/>
    <axis xyz="0 1 0"/>
  </joint>
  <!-- ROS2 Control -->
  <ros2_control name="RobotCar" type="system">
    <hardware>
      <plugin>robot_base/RobotCarHardwareInterface</plugin>
      <param name="serial_port_name">/dev/STM32</param>
      <param name="serial_baud_rate">115200</param>
      <param name="wheel_radius">0.08</param>
      <param name="wheel_separation">0.26</param>
    </hardware>
    <joint name="front_left_wheel_joint">
      <command_interface name="velocity"/>
      <state_interface name="position"/>
      <state_interface name="velocity"/>
    </joint>
    <joint name="front_right_wheel_joint">
      <command_interface name="velocity"/>
      <state_interface name="position"/>
      <state_interface name="velocity"/>
    </joint>
    <joint name="rear_left_wheel_joint">
      <command_interface name="velocity"/>
      <state_interface name="position"/>
      <state_interface name="velocity"/>
    </joint>
    <joint name="rear_right_wheel_joint">
      <command_interface name="velocity"/>
      <state_interface name="position"/>
      <state_interface name="velocity"/>
    </joint>
  </ros2_control>
</robot>
